Workbook

Sheet Instructions
A1: Holding-Accuracy and Reasoning-Grounding Annotation Workbook
A3: Purpose | B3: Complete the proposal's missing human-validation strand by checking whether each generated legal proposition states an authority's holding accurately and whether the draft's application is supported by the linked retrieval evidence.
A5: Step | B5: Required action
A6: 1. Sample | B6: Review only rows marked yes in Annotations.in_validation_sample. The deterministic stratified sample contains 50 of 59 judgments: 29 real-case inputs and 21 synthetic-case inputs (seed 748).
A7: 2. Unit | B7: Each annotation row is one cited authority/application unit. The 50 sampled judgments contain 98 such units.
A8: 3. Holding source | B8: Open the authoritative_source_url and identify the authoritative paragraph(s) that state the legal proposition actually decided.
A9: 4. Holding label | B9: yes = generated principle materially matches the source; partial = core idea is right but incomplete/overbroad; no = materially wrong or attributed to the wrong authority; unclear = source cannot resolve confidently; n/a = legislation/rule or no judicial holding.
A10: 5. Grounding evidence | B10: Filter Retrieved Evidence by the row's search_id. Record the relevant rank, case ID and chunk ID in retrieved_evidence_R1/R2.
A11: 6. Grounding label | B11: yes = the generated application is directly supported by linked retrieved material; partial = some support but an important step is unsupported; no = unsupported, contradicted or based on an unrelated source; unclear = exported evidence is insufficient; n/a = no application/grounding assessment applies.
A12: 7. Evidence notes | B12: Give a short factual reason for every label. Do not treat corpus presence alone as proof that a source was retrieved.
A13: 8. Confidence | B13: Use 1 (low) to 5 (high).
A14: 9. Reviewer 2 | B14: A second reviewer independently completes the R2 fields without reading R1 labels. Agreement and Cohen's kappa then calculate automatically.
A15: 10. Adjudication | B15: Resolve disagreements after both independent reviews; record final labels and a brief note.
... A22: Workbook status | B22: Prefilled blue cells are evidence from the audit pipeline. Pale-yellow cells are for human annotation. Do not overwrite prefilled evidence.

Sheet Sample Register
A1: Reproducible 50-Judgment Validation Sample
A2: Total judgments | B2: 59 | C2: Sampled judgments | D2: 50 | E2: Real sampled | F2: 29 | G2: Synthetic sampled | H2: 21 | I2: Sampled citation units | J2: 98 | K2: Seed | L2: 748 | M2: Method | N2: SHA-256 rank within input type | O2: Status | P2: Ready for annotation
A3: Purpose | B3: Approximately 50 generated outputs, as proposed | C3: Selection | D3: Stratified to preserve the observed real/synthetic judgment ratio | E3: Sampling unit | F3: draft_id | G3: Annotation unit | H3: citation occurrence | I3: Repeated runs | J3: Retained but not independent | K3: Primary sheets | L3: Annotations + Retrieved Evidence | M3: Agreement | N3: R1/R2 labels | O3: Do not edit | P3: Prefilled evidence
A5: sample_order | B5: in_validation_sample | C5: draft_id | D5: case_doc_id | E5: case_title | F5: input_type | G5: model_used | H5: generated_at | I5: search_id | J5: searched_at | K5: link_method | L5: citation_count | M5: average_similarity | N5: top_retrieved_case | O5: retrieved_result_count | P5: annotation_status
A6: 1 | B6: yes | C6: cmst45vlc000h04l7f6nlqawg | D6: skeleton-args-ca2015008373-db13b0c8e36da3c2 | E6: Crossfield Trading Ltd v Northern Commercial Bank Plc | F6: synthetic | G6: gpt-4o-mini | H6: 2026-08-14 15:40:27.31 | I6: cmst43r4x000b04l747yntyz2 | J6: 2026-08-14 15:38:48.135 | K6: latest_search_before_draft | L6: 1 | M6: 0.67510093 | N6: Crestsign Ltd v National Westminster Bank Plc & Anor [2015] EWCA Civ 986 | O6: 20 | P6: =IF(B6="no","not sampled",IF(COUNTIFS(Annotations!$C$2:$C$116,C6,Annotations!$AT$2:$AT$116,"complete")=COUNTIF(Annotations!$C$2:$C$116,C6),"complete","pending")) -> complete
A7: 2 | B7: yes | C7: cmmxpdot1000h04i8q3aleh7a | D7: karpasitis-v-hertfordshire-county-council | E7: Karpasitis v Hertfordshire County Council | F7: real | G7: gpt-4o-mini | H7: 2026-03-19 16:47:14.388 | I7: cmmxp9veu000b04i838upwih8 | J7: 2026-03-19 16:44:16.211 | K7: latest_search_before_draft | L7: 1 | M7: 0.69000792 | N7: Gorringe v. Calderdale Metropolitan Borough Council | O7: 20 | P7: =IF(B7="no","not sampled",IF(COUNTIFS(Annotations!$C$2:$C$116,C7,Annotations!$AT$2:$AT$116,"complete")=COUNTIF(Annotations!$C$2:$C$116,C7),"complete","pending")) -> complete
A8: 3 | B8: yes | C8: cmm0ckscr000t04i312fc6edg | D8: skeleton-args-ca2018006090-aa90566cb5f6b5de | E8: Appellant: [Name Undisclosed] v Respondent: [Name Undisclosed] | F8: synthetic | G8: gpt-4o-mini | H8: 2026-02-24 08:32:26.762 | I8: cmm0chr9w000n04i37bx1uiqp | J8: 2026-02-24 08:30:05.313 | K8: latest_search_before_draft | L8: 2 | M8: 0.67713532 | N8: Creggy v Barnett & Anor [2016] EWCA Civ 1004 (Court of Appeal (Civil Division)) | O8: 10 | P8: =IF(B8="no","not sampled",IF(COUNTIFS(Annotations!$C$2:$C$116,C8,Annotations!$AT$2:$AT$116,"complete")=COUNTIF(Annotations!$C$2:$C$116,C8),"complete","pending")) -> complete
A9: 4 | B9: yes | C9: cmst419ew000k04ladhs06s0r | D9: skeleton-args-ca2015000120-c8bbd9c0f403a8f6 | E9: Lila Sharma v Meridian Financial Services Ltd | F9: synthetic | G9: gpt-4o-mini | H9: 2026-08-14 15:36:51.942 | I9: cmst3ztkq000e04labxjacu4p | J9: 2026-08-14 15:35:44.67 | K9: latest_search_before_draft | L9: 2 | M9: 0.71589964 | N9: Kalu v Brighton and Sussex University Hospitals NHS Trust & Ors [2015] EWCA Civ 897 | O9: 20 | P9: =IF(B9="no","not sampled",IF(COUNTIFS(Annotations!$C$2:$C$116,C9,Annotations!$AT$2:$AT$116,"complete")=COUNTIF(Annotations!$C$2:$C$116,C9),"complete","pending")) -> complete
A10: 5 | B10: yes | C10: cmmc4a8zu000h04jx2w3r0hzo | D10: ca-2024-000255-ellis-v-ssj-appellant-skeleton | E10: R (Fajr Ellis) v Secretary of State for Justice | F10: real | G10: gpt-4o-mini | H10: 2026-03-04 14:13:32.296 | I10: cmmc48b4h000b04jxrxrp3idf | J10: 2026-03-04 14:12:01.647 | K10: latest_search_before_draft | L10: 2 | M10: 0.68496763 | N10: Bristow v The Secretary of State for Justice & Anor [2015] EWCA Civ 1170 | O10: 10 | P10: =IF(B10="no","not sampled",IF(COUNTIFS(Annotations!$C$2:$C$116,C10,Annotations!$AT$2:$AT$116,"complete")=COUNTIF(Annotations!$C$2:$C$116,C10),"complete","pending")) -> complete
A11: 6 | B11: yes | C11: cms1u865i000904jxu5huyjg5 | D11: ca-2024-001541-the-king-on-the-application-of-respondent-skeleton | E11: Transport Action Network Limited v Secretary of State for Transport | F11: real | G11: gpt-4o-mini | H11: 2026-07-26 13:32:31.396 | I11: cms1u714o000304jxq0x5fnl6 | J11: 2026-07-26 13:31:38.105 | K11: latest_search_before_draft | L11: 2 | M11: 0.65644003 | N11: The Howard League for Penal Reform and Prisoners' Advice Service v The Lord Chancellor | O11: 20 | P11: =IF(B11="no","not sampled",IF(COUNTIFS(Annotations!$C$2:$C$116,C11,Annotations!$AT$2:$AT$116,"complete")=COUNTIF(Annotations!$C$2:$C$116,C11),"complete","pending")) -> complete
A12: 7 | B12: yes | C12: cmomnx9nj000304jkyxxg2b0k | D12: greenfields--iow--limited-v-isle-of-wight-council---westridge-village-limited | E12: Greenfields (IOW) Limited v Isle of Wight Council & Westridge Village Limited | F12: real | G12: gpt-4o-mini | H12: 2026-05-01 08:40:25.371 | I12: cmmxtwenv000304jr7vxcmpae | J12: 2026-03-19 18:53:46.044 | K12: latest_search_before_draft | L12: 2 | M12: 0.72857795 | N12: Regina v. London Borough of Hammersmith and Fulham (Burkett) [2002] UKHL 23 | O12: 20 | P12: =IF(B12="no","not sampled",IF(COUNTIFS(Annotations!$C$2:$C$116,C12,Annotations!$AT$2:$AT$116,"complete")=COUNTIF(Annotations!$C$2:$C$116,C12),"complete","pending")) -> complete
A13: 8 | B13: yes | C13: cmmcal70d000h04k3e11w997v | D13: ew-cases-EWCA-Civ-2024-1110 | E13: UnipolSai Assicurazioni S.p.A. v Covéa Insurance Plc | F13: real | G13: gpt-4o-mini | H13: 2026-03-04 17:10:00.635 | I13: cmmcaho67000b04k3d50f98in | J13: 2026-03-04 17:07:16.148 | K13: latest_search_before_draft | L13: 2 | M13: 0.66443149 | N13: Al Mana Lifestyle Trading LLC & Ors v United Fidelity Insurance Company PSC & Ors [2023] EWCA Civ 61 | O13: 20 | P13: =IF(B13="no","not sampled",IF(COUNTIFS(Annotations!$C$2:$C$116,C13,Annotations!$AT$2:$AT$116,"complete")=COUNTIF(Annotations!$C$2:$C$116,C13),"complete","pending")) -> complete
A14: 9 | B14: yes | C14: cmm0k3nj8000h04l412ruhfxj | D14: skeleton-args-ca2024001234-346b2d683b5c2099 | E14: Transport Action Network Limited v Secretary of State for Transport | F14: synthetic | G14: gpt-4o-mini | H14: 2026-02-24 12:03:04.29 | I14: cmm0k0854000b04l440eijrw0 | J14: 2026-02-24 12:00:24.289 | K14: latest_search_before_draft | L14: 2 | M14: 0.6690264 | N14: Finch On Behalf of the Weald Action Group, R (On the Application Of) v Surrey County Council & Ors [2022] EWCA Civ 187 | O14: 10 | P14: =IF(B14="no","not sampled",IF(COUNTIFS(Annotations!$C$2:$C$116,C14,Annotations!$AT$2:$AT$116,"complete")=COUNTIF(Annotations!$C$2:$C$116,C14),"complete","pending")) -> complete
A15: 10 | B15: yes | C15: cmmafut12000904l4kjskwky4 | D15: skeleton-args-ca2025000412-e17d5e10793fe216 | E15: R (Harrison) v Secretary of State for Justice | F15: synthetic | G15: gpt-4o-mini | H15: 2026-03-03 10:01:54.804 | I15: cmmafsf07000304l4huaorple | J15: 2026-03-03 10:00:03.207 | K15: latest_search_before_draft | L15: 1 | M15: 0.64864108 | N15: The Howard League for Penal Reform and Prisoners' Advice Service v The Lord Chancellor | O15: 10 | P15: =IF(B15="no","not sampled",IF(COUNTIFS(Annotations!$C$2:$C$116,C15,Annotations!$AT$2:$AT$116,"complete")=COUNTIF(Annotations!$C$2:$C$116,C15),"complete","pending")) -> complete
A16: 11 | B16: yes | C16: cmmrr64va000h04jvzuquhz2y | D16: ca-2024-000255-ellis-v-ssj-appellant-skeleton | E16: Fajr Ellis v Secretary of State for Justice | F16: real | G16: gpt-4o-mini | H16: 2026-03-15 12:50:44.132 | I16: cmmrr3vbb000b04jvglqzb8az | J16: 2026-03-15 12:48:58.332 | K16: latest_search_before_draft | L16: 2 | M16: 0.69141448 | N16: Bristow v The Secretary of State for Justice & Anor [2015] EWCA Civ 1170 | O16: 20 | P16: =IF(B16="no","not sampled",IF(COUNTIFS(Annotations!$C$2:$C$116,C16,Annotations!$AT$2:$AT$116,"complete")=COUNTIF(Annotations!$C$2:$C$116,C16),"complete","pending")) -> complete
A17: 12 | B17: yes | C17: cmst4kl1t000h04js7g8j67zy | D17: skeleton-args-ca2019005474-f7265b45a4e3f0ae | E17: Heritage Brewing Company Ltd v Traditional Ales Holdings Plc | F17: synthetic | G17: gpt-4o-mini | H17: 2026-08-14 15:51:53.487 | I17: cmst4iu9u000b04jsb3vxyexj | J17: 2026-08-14 15:50:32.032 | K17: latest_search_before_draft | L17: 2 | M17: 0.71757606 | N17: Maier & Anor v Asos Plc & Anor [2015] EWCA Civ 220 | O17: 20 | P17: =IF(B17="no","not sampled",IF(COUNTIFS(Annotations!$C$2:$C$116,C17,Annotations!$AT$2:$AT$116,"complete")=COUNTIF(Annotations!$C$2:$C$116,C17),"complete","pending")) -> complete
... A55: 50 | B55: yes | C55: cmmjsmua2000q04jstd4i8p7c | D55: ca-2024-000255-ellis-v-ssj-appellant-skeleton | E55: Fajr Ellis v Secretary of State for Justice | F55: real | G55: gpt-4o-mini | H55: 2026-03-09 23:09:33.769 | I55: cmmjsjnvz000k04js5ptftolc | J55: 2026-03-09 23:07:05.425 | K55: latest_search_before_draft | L55: 1 | M55: 0.72093931 | N55: Velyo Velev v. Bulgaria (Application No. 16032/07) | O55: 20 | P55: =IF(B55="no","not sampled",IF(COUNTIFS(Annotations!$C$2:$C$116,C55,Annotations!$AT$2:$AT$116,"complete")=COUNTIF(Annotations!$C$2:$C$116,C55),"complete","pending")) -> complete
B56: no | C56: cmlzrzxca000304l2qk1vevzx | D56: skeleton-args-ca2023002207-ce0aafdf6d7e5716 | E56: Karpasitis v Hertfordshire County Council | F56: synthetic | G56: gpt-4o-mini | H56: 2026-02-23 22:56:21.127 | I56: cmlzry90i000b04laxzwy3gcm | J56: 2026-02-23 22:55:02.859 | K56: latest_search_before_draft | L56: 2 | M56: 0.67972329 | N56: Brown & Ors v South West Lakes Trust & Ors [2022] EWCA Civ 18 | O56: 10 | P56: =IF(B56="no","not sampled",IF(COUNTIFS(Annotations!$C$2:$C$116,C56,Annotations!$AT$2:$AT$116,"complete")=COUNTIF(Annotations!$C$2:$C$116,C56),"complete","pending")) -> not sampled
B57: no | C57: cmm3b1g6j000j04jt8w2u9z6w | D57: skeleton-args-ca2025000412-e17d5e10793fe216 | E57: R (Harrison) v Secretary of State for Justice | F57: synthetic | G57: gpt-4o-mini | H57: 2026-02-26 10:12:43.433 | I57: cmm3azb8t000d04jtx7he2awl | J57: 2026-02-26 10:11:03.637 | K57: latest_search_before_draft | L57: 2 | M57: 0.63831415 | N57: Tigere, R (On the Application Of) v Secretary of State for Business, Innovation And Skills | O57: 10 | P57: =IF(B57="no","not sampled",IF(COUNTIFS(Annotations!$C$2:$C$116,C57,Annotations!$AT$2:$AT$116,"complete")=COUNTIF(Annotations!$C$2:$C$116,C57),"complete","pending")) -> not sampled
B58: no | C58: cmmdkjytd000304jl24cdxqvp | D58: skeleton-args-ca2023004634-299a4a730fe1f43a | E58: Metropolitan Property Holdings Ltd v Artisan Coffee Co Ltd | F58: synthetic | G58: gpt-4o-mini | H58: 2026-03-05 14:36:45.694 | I58: cmmdjmbqo000b04js13axm03c | J58: 2026-03-05 14:10:36.041 | K58: latest_search_before_draft | L58: 3 | M58: 0.71504954 | N58: Freifeld & Anor v West Kensington Court Ltd [2015] EWCA Civ 806 | O58: 20 | P58: =IF(B58="no","not sampled",IF(COUNTIFS(Annotations!$C$2:$C$116,C58,Annotations!$AT$2:$AT$116,"complete")=COUNTIF(Annotations!$C$2:$C$116,C58),"complete","pending")) -> not sampled
B59: no | C59: cmsbr6p4p001704l4z7u6108h | D59: ca-2024-000806-hippodrome-casino-ltd-v-hmrc-appellant-skeleton | E59: Hippodrome Casino Ltd v HM Revenue and Customs | F59: real | G59: gpt-4o-mini | H59: 2026-08-02 12:05:05.592 | I59: cmsbr5rlu001104l45rnkob9p | J59: 2026-08-02 12:04:22.059 | K59: latest_search_before_draft | L59: 1 | M59: 0.69269881 | N59: Volkswagen Financial Services (UK) Ltd v HM Revenue & Customs | O59: 20 | P59: =IF(B59="no","not sampled",IF(COUNTIFS(Annotations!$C$2:$C$116,C59,Annotations!$AT$2:$AT$116,"complete")=COUNTIF(Annotations!$C$2:$C$116,C59),"complete","pending")) -> not sampled
B60: no | C60: cmsbsp3em001104ji2u62id7q | D60: ca-2024-000624 and ca-2024-000625-the-royal-embassy-of-saudi-arabia-appellant-skeleton | E60: Abir Alhayali v The Royal Embassy of Saudi Arabia (Cultural Bureau) | F60: real | G60: gpt-4o-mini | H60: 2026-08-02 12:47:23.517 | I60: cmsbso1ez000v04jiujckeft7 | J60: 2026-08-02 12:46:34.18 | K60: latest_search_before_draft | L60: 2 | M60: 0.67225626 | N60: Argentum Exploration Limited v The Silver and all persons claiming to be interested in and/or to have rights in respect of, the Silver [2022] EWCA Civ 1318 | O60: 20 | P60: =IF(B60="no","not sampled",IF(COUNTIFS(Annotations!$C$2:$C$116,C60,Annotations!$AT$2:$AT$116,"complete")=COUNTIF(Annotations!$C$2:$C$116,C60),"complete","pending")) -> not sampled
B61: no | C61: cmsbsqcqm001d04ji3ses9ih9 | D61: ca-2024-000624 and ca-2024-000625-the-royal-embassy-of-saudi-arabia-appellant-skeleton | E61: Abir Alhayali v The Royal Embassy of Saudi Arabia (Cultural Bureau) | F61: real | G61: gpt-4o-mini | H61: 2026-08-02 12:48:22.269 | I61: cmsbsp6wa001704jitdvkybp9 | J61: 2026-08-02 12:47:27.952 | K61: latest_search_before_draft | L61: 1 | M61: 0.67225238 | N61: Argentum Exploration Limited v The Silver and all persons claiming to be interested in and/or to have rights in respect of, the Silver [2022] EWCA Civ 1318 | O61: 20 | P61: =IF(B61="no","not sampled",IF(COUNTIFS(Annotations!$C$2:$C$116,C61,Annotations!$AT$2:$AT$116,"complete")=COUNTIF(Annotations!$C$2:$C$116,C61),"complete","pending")) -> not sampled
B62: no | C62: cmsbszs77002304ji6ldkbjce | D62: ca-2024-0023525 & ca-2024-002295-modernatx-inc-v-pfizer-limited-others-respondent-skeleton | E62: Modernatx, Inc. v Pfizer Limited & BioNTech | F62: real | G62: gpt-4o-mini | H62: 2026-08-02 12:55:42.21 | I62: cmsbsuhsv001r04jiv19ukl8u | J62: 2026-08-02 12:51:35.366 | K62: latest_search_before_draft | L62: 2 | M62: 0.68141346 | N62: Philip Morris Products, S.A. v Nicoventures Trading Limited & Anor (Re Invalidity of Patents) [2022] EWCA Civ 1638 | O62: 20 | P62: =IF(B62="no","not sampled",IF(COUNTIFS(Annotations!$C$2:$C$116,C62,Annotations!$AT$2:$AT$116,"complete")=COUNTIF(Annotations!$C$2:$C$116,C62),"complete","pending")) -> not sampled
B63: no | C63: cmsbt3hfa002904ji8k6b026n | D63: ca-2024-0023525 & ca-2024-002295-modernatx-inc-v-pfizer-limited-others-respondent-skeleton | E63: Modernatx, Inc. v Pfizer Limited & Others | F63: real | G63: gpt-4o-mini | H63: 2026-08-02 12:58:34.869 | I63: cmsbsuhsv001r04jiv19ukl8u | J63: 2026-08-02 12:51:35.366 | K63: latest_search_before_draft | L63: 2 | M63: 0.68141346 | N63: Philip Morris Products, S.A. v Nicoventures Trading Limited & Anor (Re Invalidity of Patents) [2022] EWCA Civ 1638 | O63: 20 | P63: =IF(B63="no","not sampled",IF(COUNTIFS(Annotations!$C$2:$C$116,C63,Annotations!$AT$2:$AT$116,"complete")=COUNTIF(Annotations!$C$2:$C$116,C63),"complete","pending")) -> not sampled
B64: no | C64: cmst4fdgx001l04l7p4wrw7w7 | D64: skeleton-args-ca2025001247-4e7222cd1e12236a | E64: Dr. Thornton v GlobalTech Solutions Ltd | F64: synthetic | G64: gpt-4o-mini | H64: 2026-08-14 15:47:50.383 | I64: cmst4drgk001f04l70ut5a3k0 | J64: 2026-08-14 15:46:35.115 | K64: latest_search_before_draft | L64: 2 | M64: 0.6615028 | N64: Chesterton Global Ltd & Anor v Nurmohamed & Anor | O64: 20 | P64: =IF(B64="no","not sampled",IF(COUNTIFS(Annotations!$C$2:$C$116,C64,Annotations!$AT$2:$AT$116,"complete")=COUNTIF(Annotations!$C$2:$C$116,C64),"complete","pending")) -> not sampled

Sheet Annotations
A1: sample_order | B1: in_validation_sample | C1: draft_id | D1: case_doc_id | E1: input_type | F1: citation_index | G1: citation | H1: citation_type | I1: generated_principle | J1: generated_application | K1: binding_authority | L1: citation_verification_status | M1: citation_in_linked_retrieval | N1: citation_in_corpus_registry | O1: external_case_exists | P1: external_citation_correct | Q1: authoritative_source_url | R1: search_id | S1: retrieved_case_ids | T1: retrieved_case_titles | U1: reviewer_id_R1 | V1: holding_accuracy_R1 | W1: source_paragraphs_R1 | X1: holding_evidence_R1 | Y1: reasoning_grounding_R1 | Z1: retrieved_evidence_R1 | AA1: grounding_evidence_R1 | AB1: reviewer_confidence_R1 | AC1: reviewer_date_R1 | AD1: reviewer_id_R2 | AE1: holding_accuracy_R2 | AF1: source_paragraphs_R2 | AG1: holding_evidence_R2 | AH1: reasoning_grounding_R2 | AI1: retrieved_evidence_R2 | AJ1: grounding_evidence_R2 | AK1: reviewer_confidence_R2 | AL1: reviewer_date_R2 | AM1: R3_reasoning_grounding | AN1: R3_grounding_evidence | AO1: holding_agreement | AP1: grounding_agreement | AQ1: adjudicated_holding_accuracy | AR1: adjudicated_reasoning_grounding | AS1: adjudication_notes | AT1: annotation_status
A2: 1 | B2: yes | C2: cmst45vlc000h04l7f6nlqawg | D2: skeleton-args-ca2015008373-db13b0c8e36da3c2 | E2: synthetic | F2: 1 | G2: [2000] 1 WLR 377 | H2: case_law | I2: Duty to provide adequate reasons for decisions in financial services contexts. | J2: Involves ensuring clients fully understand the risks associated with financial products sold. | K2: binding | L2: not_found_in_corpus_registry | M2: no | N2: no | O2: yes | P2: yes | Q2: https://www.bailii.org/ew/cases/EWCA/Civ/1999/811.html | R2: cmst43r4x000b04l747yntyz2 | S2: a1fcbe31-60cf-480d-aa88-19492f68df24 || 187b7b96-3c95-4093-96a7-389bc96a5dea || 5efa7b7e-80f2-4a0e-ad80-5ab0db7a9c17 || 0c0d315b-921c-4764-bbf2-256f21063551 || 4bab60a4-405b-418a-b7ed-7995d0a7b4d5 || 83821fb0-ba9c-43e6-bb47-76a85327b471 || e3367bf1-963c-47c9-aea9-8dc4a1dc25bc || a30b2ade-6e0c-4b33-a0cd-099ae990e876 || 8fd0b714-5fa9-43cf-9e51-5c74a6e3d911 || ee25b714-a850-4788-bcd3-623a5cbe4ede || b4e5eb9c-82c1-4910-beaf-c30269939bbe || 727d863a-b385-45df-96e6-d8dba00144f9 || fcbf3975-3755-45fa-9124-191d1a392003 || 50f3324e-7e20-444c-b5c6-18d53dfb80ed || c31d4c82-88f9-42c8-968b-efc3ee876ec7 || ab7f6563-ffbc-46f8-a354-e1a0f0fdf80b || c21e0bef-b8ff-4f7a-8747-96ed5c2813e1 || e55b2bcd-c806-49f1-8b91-647450f700cf || fc3a7d73-0542-421b-9be1-12f07edcfd92 || edb9880b-ba30-4e1e-a2b3-52b1d6fb2f64 | T2: Crestsign Ltd v National Westminster Bank Plc & Anor [2015] EWCA Civ 986 || Saville v Central Capital Ltd [2014] EWCA Civ 337 || Deutsche Bank AG v Unitech Global Limited & Ors [2016] EWCA Civ 119 || The Financial Conduct Authority v Ferreira [2022] EWCA Civ 397 || WW Property Investments Ltd v National Westminster Bank Plc [2016] EWCA Civ 1142 (Court of Appeal, Civil Division) || CGL Group Ltd & Ors v The Royal Bank of Scotland Plc & National Westminster Bank Plc & Ors || The Financial Conduct Authority v Capital Alternatives Ltd & Ors || Property Alliance Group Ltd v The Royal Bank of Scotland Plc [2018] EWCA Civ 355 || Banco Santander Totta SA v Companhia Carris De Ferro De Lisboa SA & Ors [2016] EWCA Civ 1267 || Electro Mechanical Installations Ltd v Royal Bank of Scotland [2014] EWCA Civ 77 || Asset Land Investment Plc & Anor v The Financial Conduct Authority (FCA) || Philipp v Barclays Bank UK Plc [2022] EWCA Civ 318 || Wood v Sureterm Direct Ltd & Capita Insurance Services Ltd [2015] EWCA Civ 839 || MTR Bailey Trading Ltd v Barclays Bank Plc [2015] EWCA Civ 667 || Figurasin & Anor v Central Capital Ltd [2014] EWCA Civ 504 || Calland v Financial Conduct Authority [2015] EWCA Civ 192 || Crossfield v Jackson [2014] EWCA Civ 1548 || O'Sullivan v Financial Services Authority [2015] EWCA Civ 896 || Group Seven Ltd & Anor v Allied Investment Corporation Ltd & Ors [2015] EWCA Civ 631 || Napier Park European Credit Opportunities Fund Ltd v Harbourmaster Pro-Rata Clo 2 B.V. & Ors [2014] EWCA Civ 984 | U2: R1 | V2: partial | W2: [2000] 1 WLR 377, 381G–382D (Henry LJ) | X2: Flannery establishes a judicial duty to give adequate reasons, particularly when resolving competing expert evidence. The generated principle preserves the general duty but incorrectly reframes it as a financial-services duty. | Y2: no | Z2: No supporting Flannery passage was retrieved. Closest results: rank 1, case ID a1fcbe31-60cf-480d-aa88-19492f68df24, chunk a1fcbe31-60cf-480d-aa88-19492f68df24_legal_classification; rank 15, case ID c31d4c82-88f9-42c8-968b-efc3ee876ec7, chunk c31d4c82-88f9-42c8-968b-efc3ee876ec7_legal_classification. | AA2: The cited authority was not retrieved. The retrieved passages concern financial-product disclosure and mis-selling generally, but they do not establish a duty to ensure that clients fully understand product risks or support the application attributed to Flannery. | AB2: 4 | AC2: 46250 | AD2: R2 | AE2: partial | AF2: 381G-382C (Henry LJ) | AG2: Ratio is the professional judge's general duty to give reasons (Henry LJ, four general comments; exceptions noted for magistrates and summary costs discretion). The duty-to-give-reasons kernel is faithful, but the judgment does not confine the duty to financial services; it arose in a valuer's negligence claim over a mortgage valuation. Context substituted rather than preserved. "Adequate" also imports the later English v Emery Reimbold standard; Flannery itself makes the required extent subject-matter dependent (comment 3). | AH2: no | AI2: search cmst43r4x...; 20 records, ranks 1-3 Crestsign / Saville / Deutsche Bank v Unitech; 16 of 20 matched on legal_classification chunks; cited authority absent | AJ2: 20 records returned; cited authority absent. 16 of 20 matched on legal_classification chunks, which are area/keyword metadata rather than propositions, so supply no premise. Remaining chunks are an unrelated swaps outcome, two citation lists and a precedent-strength note. Retrieval contains financial mis-selling material (Crestsign, Saville, Figurasin, CGL v RBS) topically adjacent to the application, but nothing supporting a reasons-based duty or the transposition from the cited authority. | AK2: 4 | AL2: 46250 | AO2: =IF(OR(V2="",AE2=""),"",IF(V2=AE2,"agree","disagree")) -> agree | AP2: =IF(OR(Y2="",AH2=""),"",IF(Y2=AH2,"agree","disagree")) -> agree | AQ2: partial | AR2: no | AS2: Holding (partial): Ratio is the professional judge's general duty to give reasons (Henry LJ, four general comments; exceptions noted for magistrates and summary costs… Grounding (no): 20 records returned; cited authority absent. 16 of 20 matched on legal_classification chunks, which are area/keyword metadata rather than propositions, so supply no premise… | AT2: =IF(B2="no","not sampled",IF(AND(V2<>"",Y2<>""),"complete","pending")) -> complete
A3: 2 | B3: yes | C3: cmmxpdot1000h04i8q3aleh7a | D3: karpasitis-v-hertfordshire-county-council | E3: real | F3: 1 | G3: English v Emery Reimbold & Strick Ltd [2002] EWCA Civ 605 | H3: case_law | I3: A judgment must provide adequate reasons for its decision | J3: The principles of adequate reasoning apply to this case regarding the justification of the maintenance practices. | K3: binding | L3: in_corpus_not_retrieved | M3: no | N3: yes | O3: yes | P3: yes | Q3: https://www.bailii.org/ew/cases/EWCA/Civ/2002/605.html | R3: cmmxp9veu000b04i838upwih8 | S3: bc30491e-9ae6-48da-90d0-71d8a8069b22 || 52d20bb9-6964-44a6-9c32-d191ef76297c || 5a42b4bc-fe8f-47be-9b13-869933b2ddff || 70d43223-0ec6-458b-b052-bdc295e0d6ec || 4840c2e7-7326-456e-84e1-def231729686 || 40629bba-06c5-4cf4-b83a-bc0badbc4848 || 6948a4df-0a45-4ddc-ae3d-8eafee44976a || e16d7203-6f9e-4896-96e0-d021cb6f5579 || 0af9689e-f55a-4b42-8c7d-e7ef4d3d1bdc || 2eaaf060-799f-4573-a18a-86e5c14b158b || 70c75405-8cba-40e2-92ff-8302ea4f6789 || 1ae781af-c482-402d-b18c-8d4c33432b24 || 653f5240-7160-47e4-9009-db4466a660e2 || 4685ad0e-87e7-4f59-8991-823ab27d9393 || 54d149f2-2e02-477e-8541-b2bf222578d6 || 353163ab-c444-4186-a05c-4f5d73800a3f || 9adfee0f-c2c7-4caa-83ed-720a548a4aab || 7351e867-1c92-49d6-a602-686678f60a5f || 57bf779f-da1f-4ee4-a60c-89018cb3b828 || 2e37836d-c57c-4eb6-942a-5a1a3a46714f | T3: Gorringe v. Calderdale Metropolitan Borough Council || King Lifting Ltd v Oxfordshire County Council [2016] EWHC 1767 (QB) || Yetkin v London Borough of Newham ([2010] EWCA Civ 776) || Brown & Ors v South West Lakes Trust & Ors [2022] EWCA Civ 18 || Butcher v Southend-On-Sea Borough Council (2014) || Dunnage v Randall & UK Insurance Ltd [2015] EWCA Civ 673 || Scott v Gavigan [2016] EWCA Civ 544 || Edwards v London Borough of Sutton [2016] EWCA Civ 1005 || Hughes v Rattan (Rev1) [2022] EWCA Civ 107 || National Grid Electricity Transmission Plc v Arnold White Estates Ltd [2014] EWCA Civ 216 || Griffiths v Gwynedd County Council [2015] EWCA Civ 1440 || HXA v Surrey County Council; YXA v Wolverhampton City Council (England and Wales Court of Appeal (Civil Division)) || Liverpool Women's Hospital NHS Foundation Trust v Ronayne [2015] EWCA Civ 588 || Tindall & Anor v Chief Constable of Thames Valley Police & Anor [2022] EWCA Civ 25 || Union of Shop, Distributive and Allied Workers & Ors v Tesco Stores Ltd (2022) EWCA Civ 978 || Paul & Ors v The Royal Wolverhampton NHS Trust; Polmear v The Royal Wolverhampton NHS Trust; Purchase v Royal Cornwall Hospitals NHS Trust || Barton & Ors v Morris & Anor [2023] UKSC 3 || Howmet Limited v Economy Devices Limited & Ors [2016] EWCA Civ 847 || Beaumont & Anor v Ferrer [2016] EWCA Civ 768 || Benyatov v Credit Suisse (Securities) Europe Ltd [2023] EWCA Civ 140 | U3: R1 | V3: yes | W3: [2002] EWCA Civ 605, paras 1–2 and 15–20 | X3: The Court of Appeal confirmed that a judgment must provide sufficient reasons to make the basis of the decision apparent. The generated principle is a materially faithful summary of that duty. | Y3: no | Z3: English v Emery was not retrieved. Closest maintenance results: rank 1, Gorringe, case ID bc30491e-9ae6-48da-90d0-71d8a8069b22, chunk bc30491e-9ae6-48da-90d0-71d8a8069b22_legal_classification; rank 2, King Lifting, case ID 52d20bb9-6964-44a6-9c32-d191ef76297c, chunk 52d20bb9-6964-44a6-9c32-d191ef76297c_legal_classification; rank 11, Griffiths, case ID 70c75405-8cba-40e2-92ff-8302ea4f6789, chunk 70c75405-8cba-40e2-92ff-8302ea4f6789_legal_classification. | AA3: The cited authority was present in the corpus but was not retrieved for this generation. The retrieved passages concern highway-maintenance duties and negligence, not the judicial duty to give adequate reasons. They do not support applying English v Emery to the justification of maintenance practices. | AB3: 5 | AC3: 46250 | AD3: R2 | AE3: yes | AF3: [16], [19]; see also [25] | AG3: Faithful one-line statement of the ratio (Lord Phillips MR at [16], [19]): the judgment must make apparent to the parties why one won and the other lost. Adequacy is case-dependent and there is no duty to address every argument ([19]), but those limits qualify the extent of the duty rather than the proposition asserted. No wrong context or duty-holder introduced. | AH3: no | AI3: search cmmxp9veu000b04i838upwih8; 20 records; cited authority absent (in corpus, not retrieved); 14/20 matched on citations_precedents chunks; ranks 1-3 Gorringe v Calderdale, King Lifting v Oxfordshire, Yetkin v Newham (legal_classification); rank 14 Tindall (legal_reasoning) | AJ3: English absent from linked retrieval. 14 of 20 records matched on citations_precedents chunks, which are bare lists of cited authorities and supply no proposition. Remainder are highway/occupiers' liability classification (Gorringe, King Lifting, Yetkin, Griffiths v Gwynedd) plus one omissions-liability reasoning chunk (Tindall). Highway-maintenance material is present, but nothing supports the reasons-adequacy principle invoked, and the application transposes a judge's duty to explain a judgment into the authority's justification of its maintenance regime. | AK3: 4 | AL3: 46251 | AO3: =IF(OR(V3="",AE3=""),"",IF(V3=AE3,"agree","disagree")) -> agree | AP3: =IF(OR(Y3="",AH3=""),"",IF(Y3=AH3,"agree","disagree")) -> agree | AQ3: yes | AR3: no | AS3: Holding (yes): Faithful one-line statement of the ratio (Lord Phillips MR at [16], [19]): the judgment must make apparent to the parties why one won and the other… Grounding (no): English absent from linked retrieval. 14 of 20 records matched on citations_precedents chunks, which are bare lists of cited authorities and supply no proposition. Remainder are… | AT3: =IF(B3="no","not sampled",IF(AND(V3<>"",Y3<>""),"complete","pending")) -> complete
A4: 3 | B4: yes | C4: cmm0ckscr000t04i312fc6edg | D4: skeleton-args-ca2018006090-aa90566cb5f6b5de | E4: synthetic | F4: 1 | G4: Armitage v Nurse [1998] Ch 241 | H4: case_law | I4: Establishes that a trustee must comply with fiduciary obligations. | J4: Reiterates the need for independent transactions to avoid self-dealing. | K4: binding | L4: not_found_in_corpus_registry | M4: no | N4: no | O4: yes | P4: yes | Q4: https://www.bailii.org/ew/cases/EWCA/Civ/1997/1279.html | R4: cmm0chr9w000n04i37bx1uiqp | S4: 4f894b7c-50f6-46f4-b08a-7d5f549411bb || 63f1ceea-1ae6-4e29-9f3b-c354ab3fba11 || af98350e-e553-4a58-8a45-9d7b2067b530 || 0f564d6f-98e5-402b-abc8-a39f1fa33427 || 5d67e6bf-5a94-4298-82ae-1f13fea951bc || a62a842c-af59-45c4-be74-800b0be5e691 || cbf9a2bb-7b6f-41be-ba0f-1a84a1e459e6 || 7d4b37f2-bfb0-4f96-a5c0-d63cd27e8dc3 || cfb9db03-44c0-4604-926a-a76e01575d88 || 8c2741c2-7eeb-471a-91de-bc6accd97a3c | T4: Creggy v Barnett & Anor [2016] EWCA Civ 1004 (Court of Appeal (Civil Division)) || Burnden Holdings (UK) Limited (in Liquidation) v Fielding & Anor [2016] EWCA Civ 557 || Santander UK Plc v R.A. Legal Solicitors [2014] EWCA Civ 183 || Cotton & Anor v Brudenell-Bruce, Earl of Cardigan & Ors [2014] EWCA Civ 1312 || Braintree District Council v Secretary of State for the Home Department & Anor [2023] EWCA Civ 727 (23 June 2023) || Hassam & Anor v Rabot & Anor; Briggs v Laditan [2023] EWCA Civ 19 || Gangat v Jassat & Anor [2022] EWCA Civ 604 || Davies v Ford & Ors [2023] EWCA Civ 167 || Floreat Investment Management Ltd v Churchill & Ors [2023] EWCA Civ 440 || Barnsley & Ors v Noble (Rev1) [2016] EWCA Civ 799 (Court of Appeal, Civil Division) | U4: R1 | V4: partial | W4: [1998] Ch 241, 253H–254B and 254E–256A (Millett LJ) | X4: Armitage concerned the scope and validity of trustee exemption clauses. It recognised an irreducible obligation to perform the trust honestly and in good faith, but permitted exemption from liability for other breaches. The generated principle is broadly related but omits this central context and overstates the holding as a general requirement to comply with all fiduciary obligations. | Y4: partial | Z4: Rank 10, Barnsley v Noble, case ID 8c2741c2-7eeb-471a-91de-bc6accd97a3c, chunk 8c2741c2-7eeb-471a-91de-bc6accd97a3c_case_analysis, discusses self-dealing, transaction and exoneration clauses and cites Armitage. Rank 4, Cotton v Brudenell-Bruce, case ID 0f564d6f-98e5-402b-abc8-a39f1fa33427, chunk 0f564d6f-98e5-402b-abc8-a39f1fa33427_case_analysis, concerns trustee conduct, property sales, honesty and disclosure. | AA4: The linked retrieval provides limited support that self-dealing and conflicts are relevant to trustee transactions. However, Armitage was not retrieved as a standalone case, and no passage establishes a requirement for “independent transactions.” The application therefore exceeds the retrieved evidence. | AB4: 4 | AC4: 46250 | AD4: R2 | AE4: partial | AF4: ~251-256 (Millett LJ: irreducible core; cl 15 exemption) | AG4: Principal issue was the validity of a trustee exemption clause (cl 15): liability for breach including gross negligence may be excluded, but not for fraud or dishonesty; an irreducible core of honesty and good faith survives (Millett LJ, ~251-256). The generated principle is a vague generality that omits that context and sits awkwardly with the ratio, since Armitage confirms duties of care can be excluded. | AH4: no | AI4: search cmm0chr9w000n04i37bx1uiqp; 10 records (cf 20 elsewhere); cited authority absent and not in corpus registry; 6/10 case_analysis, 3/10 procedural_history, 1/10 legal_reasoning; rank 10 Barnsley v Noble closest (exoneration clause applied to self-dealing); ranks 4 Cotton v Brudenell-Bruce, 9 Floreat (fiduciary duties) | AJ4: Armitage absent from retrieval and not in corpus registry. Only 10 records returned; 6 of 10 matched case_analysis chunks (precedent-strength and complexity scores, i.e. evaluative metadata rather than propositions) and 3 procedural_history chunks (court/judge/date listings, two unrelated: Braintree planning, Hassam whiplash). Rank 10 Barnsley v Noble references exoneration clauses applied to self-dealing and rank 4 Cotton v Brudenell-Bruce fiduciary duty, so fiduciary material is topically present, but no retrieved chunk states a self-dealing proposition. Application invokes the self-dealing rule, a doctrine distinct from the cited authority's ratio. | AK4: 3 | AL4: 46251 | AO4: =IF(OR(V4="",AE4=""),"",IF(V4=AE4,"agree","disagree")) -> agree | AP4: =IF(OR(Y4="",AH4=""),"",IF(Y4=AH4,"agree","disagree")) -> disagree | AQ4: partial | AR4: no | AS4: Holding (partial): Principal issue was the validity of a trustee exemption clause (cl 15): liability for breach including gross negligence may be excluded, but not for… Grounding (no): Armitage absent from retrieval and not in corpus registry. Only 10 records returned; 6 of 10 matched case_analysis chunks (precedent-strength and complexity scores, i.e. evaluative… | AT4: =IF(B4="no","not sampled",IF(AND(V4<>"",Y4<>""),"complete","pending")) -> complete
A5: 3 | B5: yes | C5: cmm0ckscr000t04i312fc6edg | D5: skeleton-args-ca2018006090-aa90566cb5f6b5de | E5: synthetic | F5: 2 | G5: Spread Trustee Co Ltd v Hutcheson [2011] UKPC 13 | H5: case_law | I5: Reiterates the necessity of diligent investment by trustees. | J5: Clarifies fiduciary duties and potential breaches based on performance metrics. | K5: binding | L5: not_found_in_corpus_registry | M5: no | N5: no | O5: yes | P5: yes | Q5: https://jcpc.uk/cases/jcpc-2010-0007 | R5: cmm0chr9w000n04i37bx1uiqp | S5: 4f894b7c-50f6-46f4-b08a-7d5f549411bb || 63f1ceea-1ae6-4e29-9f3b-c354ab3fba11 || af98350e-e553-4a58-8a45-9d7b2067b530 || 0f564d6f-98e5-402b-abc8-a39f1fa33427 || 5d67e6bf-5a94-4298-82ae-1f13fea951bc || a62a842c-af59-45c4-be74-800b0be5e691 || cbf9a2bb-7b6f-41be-ba0f-1a84a1e459e6 || 7d4b37f2-bfb0-4f96-a5c0-d63cd27e8dc3 || cfb9db03-44c0-4604-926a-a76e01575d88 || 8c2741c2-7eeb-471a-91de-bc6accd97a3c | T5: Creggy v Barnett & Anor [2016] EWCA Civ 1004 (Court of Appeal (Civil Division)) || Burnden Holdings (UK) Limited (in Liquidation) v Fielding & Anor [2016] EWCA Civ 557 || Santander UK Plc v R.A. Legal Solicitors [2014] EWCA Civ 183 || Cotton & Anor v Brudenell-Bruce, Earl of Cardigan & Ors [2014] EWCA Civ 1312 || Braintree District Council v Secretary of State for the Home Department & Anor [2023] EWCA Civ 727 (23 June 2023) || Hassam & Anor v Rabot & Anor; Briggs v Laditan [2023] EWCA Civ 19 || Gangat v Jassat & Anor [2022] EWCA Civ 604 || Davies v Ford & Ors [2023] EWCA Civ 167 || Floreat Investment Management Ltd v Churchill & Ors [2023] EWCA Civ 440 || Barnsley & Ors v Noble (Rev1) [2016] EWCA Civ 799 (Court of Appeal, Civil Division) | U5: R1 | V5: partial | W5: [3]–[5], [20]–[23], [80] | X5: [20] confirms the duty to act as a reasonable and prudent trustee with reasonable care and skill. However, [3]–[5] and [21]–[23] show that the appeal concerned exoneration from liability for gross negligence under Guernsey law. The Board did not determine whether the alleged investment conduct constituted a breach. The generated principle therefore captures a general duty-of-care idea but mischaracterises the case as an investment-diligence holding. | Y5: partial | Z5: Rank 10, Barnsley v Noble, chunk 8c2741c2-7eeb-471a-91de-bc6accd97a3c_case_analysis, discusses trustee exoneration clauses and fiduciary duties and lists Spread Trustee among the cited cases. | AA5: The retrieval provides limited support for the general fiduciary-duty/exoneration theme. It does not support assessing breaches through performance metrics, and the Spread Trustee judgment itself was not retrieved as a standalone authority. | AB5: 4 | AC5: 46250 | AD5: R2 | AE5: no | AF5: [54]-[61], [111]; Baroness Hale and Lord Kerr dissenting | AG5: Appeal from Guernsey. Sole issue was whether a trust deed could exclude a trustee's liability for gross negligence before the Trusts (Amendment) (Guernsey) Law 1990. Held 3-2 that Guernsey customary law and s.34(7) of the 1989 Law permitted such exclusion, the 1990 prohibition not being retrospective. The judgment says nothing about a duty of diligent investment; investment duties were not in issue. Proposition attributed is not established by the authority. | AH5: no | AI5: search cmm0chr9w000n04i37bx1uiqp (shared with citation_index 1); 10 records; cited authority absent and not in corpus registry; 6/10 case_analysis, 3/10 procedural_history, 1/10 legal_reasoning; nearest fiduciary material at ranks 4 Cotton v Brudenell-Bruce, 9 Floreat, 10 Barnsley v Noble; no investment or performance material at any rank | AJ5: Spread Trustee absent from retrieval and not in corpus registry. The 10 records concern limitation for trust claims (Creggy, Burnden), solicitors' handling of trust funds (Santander), trustee conduct in property sales (Cotton), dishonest assistance and constructive trusts (Floreat) and exoneration clauses (Barnsley), plus three procedural_history listings, two unrelated. Nothing addresses investment duties or performance-based assessment of breach, so the application's premise is absent from the linked retrieval entirely. | AK5: 4 | AL5: 46251 | AO5: =IF(OR(V5="",AE5=""),"",IF(V5=AE5,"agree","disagree")) -> disagree | AP5: =IF(OR(Y5="",AH5=""),"",IF(Y5=AH5,"agree","disagree")) -> disagree | AQ5: no | AR5: no | AS5: Holding (no): The appeal decided whether Guernsey law permitted exclusion of gross-negligence liability, not a duty of diligent investment; the attributed… Grounding (no): Spread Trustee absent from retrieval and not in corpus registry. The 10 records concern limitation for trust claims (Creggy, Burnden), solicitors' handling of trust funds… | AT5: =IF(B5="no","not sampled",IF(AND(V5<>"",Y5<>""),"complete","pending")) -> complete
A6: 4 | B6: yes | C6: cmst419ew000k04ladhs06s0r | D6: skeleton-args-ca2015000120-c8bbd9c0f403a8f6 | E6: synthetic | F6: 1 | G6: Shamoon v Chief Constable of the Royal Ulster Constabulary | H6: case_law | I6: Direct discrimination can be established by examining the circumstances surrounding the treatment of the employee. | J6: Applicable here as microaggressions create an environment of perceived discrimination. | K6: persuasive | L6: not_found_in_corpus_registry | M6: no | N6: no | O6: yes | P6: incomplete | Q6: https://publications.parliament.uk/pa/ld200203/ldjudgmt/jd030227/sham-1.htm | R6: cmst3ztkq000e04labxjacu4p | S6: b5913f39-0611-4550-b7a3-d97e1fc4f9c9 || 060fb5e3-4e14-487d-89e2-170c04ebf40c || 7b9b0d5a-dc61-43d4-9626-d82e18f8c8dd || 9ae4bb2e-75ef-4733-a35d-66d61620f6e5 || 3b44a16a-76b8-49d4-8f00-6e1767c46005 || 9106dcdb-cf09-4bda-8712-36474df03834 || 29190db1-6f4f-49a2-84d9-84e5a2091581 || 9505adbf-4b10-41b0-bc0d-d71d70aa9210 || 87fe7360-158a-49e4-8725-7a68e18ba9ac || 48b2068c-80e9-4d0c-81f5-46a177a4c560 || d6938848-6263-4913-8294-68c6e5aca496 || 9365ac87-002c-4767-beb5-daa394718251 || e740795c-9249-45f8-aba9-1ab82a3274ca || 4b1144b2-2c97-48a1-8fd0-8ebbb0e8a2ce || e099b583-4ed3-4598-a6cb-0f3565312f05 || d0274784-a003-4439-8e79-06947376b0e7 || b6038737-31bb-4cfe-ba4c-5199070a3616 || 71cd4995-e726-4ac0-861a-ef9b3e0c3f4d || 58d08b20-69c9-47be-8f81-5be69b31e088 || c7763be7-d3d8-4e78-acc8-2eae10851872 | T6: Kalu v Brighton and Sussex University Hospitals NHS Trust & Ors [2015] EWCA Civ 897 || Gaurilcikiene v Tesco Stores Ltd [2014] EWCA Civ 1213 || South Wales Police Authority v Johnson [2014] EWCA Civ 73 || Home Office (UK Border Agency) v Essop & Ors || Khan v Royal Mail Group Ltd & Ors [2014] EWCA Civ 1082 || Agbenowossi-Koffi v Donvand Ltd [2014] EWCA Civ 855 || Jafri v Lincoln College [2014] EWCA Civ 449 || Ayodele v Citylink Ltd & Anor || Coventry University v Mian [2014] EWCA Civ 1275 || Burrell v Micheldever Tyre Services Ltd || Xerox (UK) Ltd & Ors v Zeb [2017] EWCA Civ 2137 || Adeshina v St. George's University Hospitals NHS Foundation Trust & Ors [2017] EWCA Civ 257 || Gala Tent Ltd v Chambers & Anor [2015] EWCA Civ 1063 || Ahir v British Airways Plc [2017] EWCA Civ 1392 || Pye v Queen Mary University of London [2017] EWCA Civ 1820 || CLFIS (UK) Ltd v Reynolds || Shrestha v Genesis Housing Association Ltd [2015] EWCA Civ 94 || Rochford v WNS Global Services (UK) Ltd & Ors [2017] EWCA Civ 2205 || Kuznetsov v The Royal Bank of Scotland Plc || Bhardwaj v FDA & Ors [2015] EWCA Civ 658 | U6: R1 | V6: partial | W6: [3]–[12], [14]–[15] | X6: [3]–[4] identify the elements of direct discrimination as less favourable treatment on a prohibited ground, using an actual or hypothetical comparator whose circumstances are materially the same. [8]–[12] explain that the comparator and reason-why questions may be intertwined and that the tribunal may examine all the facts to determine why the treatment occurred. The generated principle captures the relevance of surrounding circumstances but omits the comparator, less-favourable-treatment and prohibited-ground requirements. | Y6: no | Z6: Rank 1 Kalu, chunk b5913f39-0611-4550-b7a3-d97e1fc4f9c9_case_analysis; rank 2 Gaurilcikiene, chunk 060fb5e3-4e14-487d-89e2-170c04ebf40c_case_analysis; and rank 3 South Wales Police Authority v Johnson, chunk 7b9b0d5a-dc61-43d4-9626-d82e18f8c8dd_case_analysis. These contain only general discussion of discrimination claims, evidence and burden of proof. | AA6: one of the retrieved passages mentions microaggressions, a discriminatory environment or facts establishing that the alleged treatment occurred because of a protected characteristic. A perceived discriminatory environment is also not, without more, the direct-discrimination test stated in Shamoon. | AB6: 4 | AC6: 46250 | AD6: R2 | AE6: partial | AF6: [7]-[12] (Lord Nicholls); [64]-[74] (Lord Hope); [110]-[136] (Lord Scott) | AG6: HL, NI appeal. Lord Nicholls's guidance is that tribunals may avoid the rigid two-stage less-favourable-treatment/comparator sequence and instead ask directly why the claimant was treated as she was, since the two questions are intertwined; the comparator must be someone whose relevant circumstances are the same (s.7 NI Order 1976 / RRA analogue). The generated principle captures the shift toward examining surrounding circumstances but omits the essentials: the requirement of less favourable treatment than a genuine comparator, the "reason why" question, and that the guidance concerns the order of tribunal enquiry rather than a free-standing route to establishing discrimination. Correct general idea, important test omitted. | AH6: no | AI6: search cmst3ztkq000e04labxjacu4p; 20 records, 20/20 case_analysis; cited authority absent and not in corpus registry; ranks 1-5 Kalu, Gaurilcikiene, South Wales Police v Johnson, Home Office v Essop, Khan v Royal Mail; sim band 0.706-0.735 | AJ6: Shamoon absent from retrieval and not in corpus registry. All 20 records matched on case_analysis chunks, which are precedent-strength and complexity scores (each ending "Confidence: 85%") rather than legal propositions, so none supplies a premise. The retrieved cases are discrimination and employment matters (Kalu, Gaurilcikiene, Essop, Khan, Ayodele) and are topically adjacent, but nothing addresses microaggressions, perceived discrimination, or a comparator/"reason why" analysis. The application also advances a proposition the cited authority does not support: Shamoon requires less favourable treatment than a comparator, not an environment of perceived discrimination. | AK6: 4 | AL6: 46251 | AO6: =IF(OR(V6="",AE6=""),"",IF(V6=AE6,"agree","disagree")) -> agree | AP6: =IF(OR(Y6="",AH6=""),"",IF(Y6=AH6,"agree","disagree")) -> agree | AQ6: partial | AR6: no | AS6: Holding (partial): HL, NI appeal. Lord Nicholls's guidance is that tribunals may avoid the rigid two-stage less-favourable-treatment/comparator sequence and instead ask… Grounding (no): Shamoon absent from retrieval and not in corpus registry. All 20 records matched on case_analysis chunks, which are precedent-strength and complexity scores (each ending… | AT6: =IF(B6="no","not sampled",IF(AND(V6<>"",Y6<>""),"complete","pending")) -> complete
A7: 4 | B7: yes | C7: cmst419ew000k04ladhs06s0r | D7: skeleton-args-ca2015000120-c8bbd9c0f403a8f6 | E7: synthetic | F7: 2 | G7: Igen Ltd v Wong | H7: case_law | I7: The burden of proof shifts to the employer when a claimant establishes a prima facie case. | J7: Relevant to the allegations of discrimination and the Respondent’s burden of explaining performance-related dismissals. | K7: binding | L7: not_found_in_corpus_registry | M7: no | N7: no | O7: yes | P7: incomplete | Q7: https://www.bailii.org/ew/cases/EWCA/Civ/2005/142.html | R7: cmst3ztkq000e04labxjacu4p | S7: b5913f39-0611-4550-b7a3-d97e1fc4f9c9 || 060fb5e3-4e14-487d-89e2-170c04ebf40c || 7b9b0d5a-dc61-43d4-9626-d82e18f8c8dd || 9ae4bb2e-75ef-4733-a35d-66d61620f6e5 || 3b44a16a-76b8-49d4-8f00-6e1767c46005 || 9106dcdb-cf09-4bda-8712-36474df03834 || 29190db1-6f4f-49a2-84d9-84e5a2091581 || 9505adbf-4b10-41b0-bc0d-d71d70aa9210 || 87fe7360-158a-49e4-8725-7a68e18ba9ac || 48b2068c-80e9-4d0c-81f5-46a177a4c560 || d6938848-6263-4913-8294-68c6e5aca496 || 9365ac87-002c-4767-beb5-daa394718251 || e740795c-9249-45f8-aba9-1ab82a3274ca || 4b1144b2-2c97-48a1-8fd0-8ebbb0e8a2ce || e099b583-4ed3-4598-a6cb-0f3565312f05 || d0274784-a003-4439-8e79-06947376b0e7 || b6038737-31bb-4cfe-ba4c-5199070a3616 || 71cd4995-e726-4ac0-861a-ef9b3e0c3f4d || 58d08b20-69c9-47be-8f81-5be69b31e088 || c7763be7-d3d8-4e78-acc8-2eae10851872 | T7: Kalu v Brighton and Sussex University Hospitals NHS Trust & Ors [2015] EWCA Civ 897 || Gaurilcikiene v Tesco Stores Ltd [2014] EWCA Civ 1213 || South Wales Police Authority v Johnson [2014] EWCA Civ 73 || Home Office (UK Border Agency) v Essop & Ors || Khan v Royal Mail Group Ltd & Ors [2014] EWCA Civ 1082 || Agbenowossi-Koffi v Donvand Ltd [2014] EWCA Civ 855 || Jafri v Lincoln College [2014] EWCA Civ 449 || Ayodele v Citylink Ltd & Anor || Coventry University v Mian [2014] EWCA Civ 1275 || Burrell v Micheldever Tyre Services Ltd || Xerox (UK) Ltd & Ors v Zeb [2017] EWCA Civ 2137 || Adeshina v St. George's University Hospitals NHS Foundation Trust & Ors [2017] EWCA Civ 257 || Gala Tent Ltd v Chambers & Anor [2015] EWCA Civ 1063 || Ahir v British Airways Plc [2017] EWCA Civ 1392 || Pye v Queen Mary University of London [2017] EWCA Civ 1820 || CLFIS (UK) Ltd v Reynolds || Shrestha v Genesis Housing Association Ltd [2015] EWCA Civ 94 || Rochford v WNS Global Services (UK) Ltd & Ors [2017] EWCA Civ 2205 || Kuznetsov v The Royal Bank of Scotland Plc || Bhardwaj v FDA & Ors [2015] EWCA Civ 658 | U7: R1 | V7: yes | W7: [71]–[76], especially [76] Annex items (1), (2) and (9)–(13) | X7: The guidance annexed at [76] provides that the claimant must first prove facts from which the tribunal could conclude, absent an adequate explanation, that unlawful discrimination occurred. Once those facts are proved, the burden passes to the respondent to prove that the treatment was in no sense based on the prohibited ground. The generated principle materially and accurately summarises this two-stage rule. | Y7: yes | Z7: Rank 3, South Wales Police Authority v Johnson, chunk 7b9b0d5a-dc61-43d4-9626-d82e18f8c8dd_case_analysis, discusses burden of proof and evidential sufficiency and expressly cites Igen. Rank 5, Khan v Royal Mail Group, chunk 3b44a16a-76b8-49d4-8f00-6e1767c46005_case_analysis, states that Igen and Madarassy govern discrimination burdens. Rank 8, Ayodele v Citylink, chunk 9505adbf-4b10-41b0-bc0d-d71d70aa9210_case_analysis, confirms the section 136 burden-of-proof framework and cites Igen. | AA7: The retrieved passages directly support applying the burden-shifting framework to employment discrimination allegations. Ranks 17 and 18 additionally concern employee conduct, dismissal and employer explanations. Read with the generated principle’s prima-facie-case condition, the application does not materially exceed the retrieval evidence. | AB7: 4 | AC7: 46251 | AD7: R2 | AE7: yes | AF7: ~[17]-[27] and revised Barton guidance at Annex (Peter Gibson LJ) — verify pinpoints on BAILII | AG7: CA, three conjoined appeals (Igen v Wong; Chamberlin Solicitors v Emokpae; Brunel University v Webster). Revised the Barton v Investec guidelines on the two-stage burden of proof under s.63A SDA 1975 / s.54A RRA 1976: the claimant must first prove facts from which the tribunal could conclude, absent an adequate explanation, that the respondent committed an unlawful act; the burden then passes to the respondent to prove it did not discriminate. The generated principle is a compressed but faithful statement of that shift. "Prima facie case" is not the judgment's own language and glosses the "could conclude" threshold later clarified in Madarassy v Nomura, but this is compression rather than an omitted limitation. | AH7: partial | AI7: search cmst3ztkq000e04labxjacu4p (shared with citation_index 1); 20 records, 20/20 case_analysis; cited authority absent as a record but named in rank 5 chunk text; rank 5 Khan v Royal Mail (references Igen Ltd v Wong and Madarassy v Nomura), rank 8 Ayodele v Citylink (burden of proof, s.136 Equality Act), rank 3 South Wales Police v Johnson (burden of proof in race discrimination), rank 4 Essop (indirect discrimination and burden of proof) | AJ7: Igen absent from retrieval as a record and not in corpus registry, but the linked retrieval is squarely on topic: four chunks concern the burden of proof in discrimination claims, and rank 5 names Igen v Wong and Madarassy expressly. That supplies genuine relevance to the application's claim that the respondent bears a burden of explanation. It is insufficient, however, because all 20 records are case_analysis precedent-strength commentary: they reference burden of proof as a subject descriptor without stating the two-stage test or any proposition from which the application's step could be drawn. Relevant but insufficient for the full application. | AK7: 3 | AL7: 46251 | AO7: =IF(OR(V7="",AE7=""),"",IF(V7=AE7,"agree","disagree")) -> agree | AP7: =IF(OR(Y7="",AH7=""),"",IF(Y7=AH7,"agree","disagree")) -> disagree | AQ7: yes | AR7: partial | AS7: Holding (yes): CA, three conjoined appeals (Igen v Wong; Chamberlin Solicitors v Emokpae; Brunel University v Webster). Revised the Barton v Investec guidelines on… Grounding (partial): Igen absent from retrieval as a record and not in corpus registry, but the linked retrieval is squarely on topic: four chunks concern the burden of proof in discrimination claims… | AT7: =IF(B7="no","not sampled",IF(AND(V7<>"",Y7<>""),"complete","pending")) -> complete
A8: 5 | B8: yes | C8: cmmc4a8zu000h04jx2w3r0hzo | D8: ca-2024-000255-ellis-v-ssj-appellant-skeleton | E8: real | F8: 1 | G8: R (Johnson) v SSHD | H8: case_law | I8: Threshold for breach of rights requires evaluation of proportionality against security concerns in prison settings. | J8: Evaluated the balance of rights against institutional security measures. | K8: binding | L8: not_found_in_corpus_registry | M8: no | N8: no | O8: ambiguous | P8: no | Q8: https://www.supremecourt.uk/cases/uksc-2016-0042 | R8: cmmc48b4h000b04jxrxrp3idf | S8: 1dbb4242-42ac-456f-989f-5098066d87ca || d60a5323-796e-4110-a6de-012ec16860c1 || 6704e94e-e6b0-4dfe-b4c9-c5d695bdc6aa || 9826ea30-d68f-4beb-b85e-e38b5e1c7cae || be44e528-bdba-4691-afcc-c607a89fd1dc || f78142fc-13ea-4fb5-9a5e-1efbdc8d3c38 || e99652af-372a-448f-8251-a215010e8b3a || de4a5f2b-b3c7-4369-9020-dcc807bb315b || 5bc05b2e-6b7d-4270-b799-9d29ed174d14 || 3e059541-8504-4163-a05b-ede4202b7675 | T8: Bristow v The Secretary of State for Justice & Anor [2015] EWCA Civ 1170 || The Howard League for Penal Reform and Prisoners' Advice Service v The Lord Chancellor || Pearce, R (On the Application Of) v Parole Board of England and Wales & Anor [2022] EWCA Civ 4 || C3 & Anor v The Secretary of State for Foreign, Commonwealth & Development Affairs [2023] EWCA Civ 444 || R (On the Application Of) v Secretary of State for the Home Department (Rev1) [2022] EWCA Civ 30 || AAA (Syria) & Ors v Secretary of State for the Home Department [2023] EWCA Civ 266 || Richards, R (On the Application Of) v The Environment Agency [2022] EWCA Civ 26 || Elkundi, R (On the Application Of) v Birmingham City Council [2022] EWCA Civ 601 || MD & Anor v Secretary of State for the Home Department [2022] EWCA Civ 336 || Cleeland, R (On the Application Of) v Criminal Cases Review Commission [2022] EWCA Civ 5 | U8: R1 | V8: no | W8: [1]–[2], [20]–[23], [27]–[35] | X8: [1]–[2] identify the case as concerning discriminatory denial of British citizenship and consequential deportation liability. [27]–[30] address Articles 8 and 14 and the proportionality of discrimination based on birth outside marriage. [34]–[35] hold that the present deportation distinction lacked justification. The case does not establish a threshold balancing prisoners’ rights against institutional security. | Y8: no | Z8: Rank 1, Bristow v Secretary of State for Justice, chunk 1dbb4242-42ac-456f-989f-5098066d87ca_legal_classification, contains only a broad classification covering prisoner rights, Article 14 and public law. Rank 2, Howard League for Penal Reform v Lord Chancellor, chunk d60a5323-796e-4110-a6de-012ec16860c1_case_analysis, concerns prisoners’ legal aid, fair-trial rights and access to justice. Ranks 3–10 are predominantly procedural histories unrelated to the asserted balancing exercise. | AA8: The retrieved material does not discuss institutional security measures or a proportionality balance between those measures and prisoners’ rights. General references to human rights and prison law are insufficient to support the generated application. | AB8: 4 | AC8: 46251 | AD8: R2 | AE8: unclear | AF8: n/a - authority not reliably identifiable | AG8: Citation is name-only with no year or report reference, and R (Johnson) v SSHD matches several distinct authorities. The URL recorded in column Q resolves to UKSC 2016-0042, R (Johnson) v SSHD [2016] UKSC 56, which concerns automatic deportation and Article 14 discrimination arising from illegitimacy at birth, not proportionality or prison security. The draft concerns Ellis v Secretary of State for Justice; prison conditions fall to the MoJ rather than the Home Office, so the named respondent is also inconsistent with the proposition. The intended authority cannot be determined without substituting a different case, which §10 prohibits. unclear under §4 (source cannot be reliably obtained), recorded rather than resolved. | AH8: no | AI8: search cmmc48b4h000b04jxrxrp3idf (shared with citation_index 2); 10 records; 8/10 procedural_history, rank 1 Bristow v SSJ (legal_classification: Administrative Law, Human Rights, Prison Law, Article 14 ECHR, Repatriation of Prisoners Act), rank 2 Howard League v Lord Chancellor (case_analysis: prisoner legal aid, ECHR fair trial, access to justice); sim band 0.678-0.697 | AJ8: Eight of ten records matched on procedural_history chunks listing court, judges, case numbers and hearing dates with no legal content. Ranks 1 and 2 are topically adjacent — prisoner rights, Article 14, ECHR — and are the strongest material in the retrieval, but rank 1 is a taxonomy chunk naming legal areas without stating any test, and rank 2 is precedent-strength commentary on legal aid. Nothing supplies a proportionality framework or any premise for balancing rights against institutional security. Assessed against the retrieval independently of the unresolved citation. | AK8: 2 | AL8: 46251 | AO8: =IF(OR(V8="",AE8=""),"",IF(V8=AE8,"agree","disagree")) -> disagree | AP8: =IF(OR(Y8="",AH8=""),"",IF(Y8=AH8,"agree","disagree")) -> agree | AQ8: no | AR8: no | AS8: Holding (no): The supplied authoritative source resolves to Johnson [2016] UKSC 56, which concerns deportation and Article 14 discrimination rather than prison… Grounding (no): Eight of ten records matched on procedural_history chunks listing court, judges, case numbers and hearing dates with no legal content. Ranks 1 and 2 are topically adjacent —… | AT8: =IF(B8="no","not sampled",IF(AND(V8<>"",Y8<>""),"complete","pending")) -> complete
